In process #10
Process #10 done!
Process Process-16:
Traceback (most recent call last):
  File "/usr/lib64/python2.6/multiprocessing/process.py", line 232, in _bootstrap
    self.run()
  File "/usr/lib64/python2.6/multiprocessing/process.py", line 88, in run
    self._target(*self._args, **self._kwargs)
  File "Strong_Paths.py", line 25, in legit
    if float(os.path.getsize(sys.argv[2]+'/'+str(process_num)+'_'+str(i)+'.txt'))/size_of_line >=min_points:
  File "/usr/lib64/python2.6/genericpath.py", line 49, in getsize
    return os.stat(filename).st_size
OSError: [Errno 2] No such file or directory: '/scratch/user/architsh/PathSegmentsApril2013/16_13268.txt'
In process #16
In process #18
Process #18 done!
Process Process-6:
Traceback (most recent call last):
  File "/usr/lib64/python2.6/multiprocessing/process.py", line 232, in _bootstrap
    self.run()
  File "/usr/lib64/python2.6/multiprocessing/process.py", line 88, in run
    self._target(*self._args, **self._kwargs)
  File "Strong_Paths.py", line 25, in legit
    if float(os.path.getsize(sys.argv[2]+'/'+str(process_num)+'_'+str(i)+'.txt'))/size_of_line >=min_points:
  File "/usr/lib64/python2.6/genericpath.py", line 49, in getsize
    return os.stat(filename).st_size
OSError: [Errno 2] No such file or directory: '/scratch/user/architsh/PathSegmentsApril2013/6_14940.txt'
In process #6
In process #13
Process #13 done!
Process Process-12:
Traceback (most recent call last):
  File "/usr/lib64/python2.6/multiprocessing/process.py", line 232, in _bootstrap
    self.run()
  File "/usr/lib64/python2.6/multiprocessing/process.py", line 88, in run
    self._target(*self._args, **self._kwargs)
  File "Strong_Paths.py", line 25, in legit
    if float(os.path.getsize(sys.argv[2]+'/'+str(process_num)+'_'+str(i)+'.txt'))/size_of_line >=min_points:
  File "/usr/lib64/python2.6/genericpath.py", line 49, in getsize
    return os.stat(filename).st_size
OSError: [Errno 2] No such file or directory: '/scratch/user/architsh/PathSegmentsApril2013/12_15953.txt'
In process #12
In process #20
Process #20 done!
Process Process-9:
Traceback (most recent call last):
  File "/usr/lib64/python2.6/multiprocessing/process.py", line 232, in _bootstrap
    self.run()
  File "/usr/lib64/python2.6/multiprocessing/process.py", line 88, in run
    self._target(*self._args, **self._kwargs)
  File "Strong_Paths.py", line 25, in legit
    if float(os.path.getsize(sys.argv[2]+'/'+str(process_num)+'_'+str(i)+'.txt'))/size_of_line >=min_points:
  File "/usr/lib64/python2.6/genericpath.py", line 49, in getsize
    return os.stat(filename).st_size
OSError: [Errno 2] No such file or directory: '/scratch/user/architsh/PathSegmentsApril2013/9_17787.txt'
In process #9
In process #1
Process #1 done!
Process Process-4:
Traceback (most recent call last):
  File "/usr/lib64/python2.6/multiprocessing/process.py", line 232, in _bootstrap
    self.run()
  File "/usr/lib64/python2.6/multiprocessing/process.py", line 88, in run
    self._target(*self._args, **self._kwargs)
  File "Strong_Paths.py", line 25, in legit
    if float(os.path.getsize(sys.argv[2]+'/'+str(process_num)+'_'+str(i)+'.txt'))/size_of_line >=min_points:
  File "/usr/lib64/python2.6/genericpath.py", line 49, in getsize
    return os.stat(filename).st_size
OSError: [Errno 2] No such file or directory: '/scratch/user/architsh/PathSegmentsApril2013/4_23457.txt'
In process #4
In process #2
Process #2 done!
Process Process-11:
Traceback (most recent call last):
  File "/usr/lib64/python2.6/multiprocessing/process.py", line 232, in _bootstrap
    self.run()
  File "/usr/lib64/python2.6/multiprocessing/process.py", line 88, in run
    self._target(*self._args, **self._kwargs)
  File "Strong_Paths.py", line 25, in legit
    if float(os.path.getsize(sys.argv[2]+'/'+str(process_num)+'_'+str(i)+'.txt'))/size_of_line >=min_points:
  File "/usr/lib64/python2.6/genericpath.py", line 49, in getsize
    return os.stat(filename).st_size
OSError: [Errno 2] No such file or directory: '/scratch/user/architsh/PathSegmentsApril2013/11_25957.txt'
In process #11
Process Process-14:
Traceback (most recent call last):
  File "/usr/lib64/python2.6/multiprocessing/process.py", line 232, in _bootstrap
    self.run()
  File "/usr/lib64/python2.6/multiprocessing/process.py", line 88, in run
    self._target(*self._args, **self._kwargs)
  File "Strong_Paths.py", line 25, in legit
    if float(os.path.getsize(sys.argv[2]+'/'+str(process_num)+'_'+str(i)+'.txt'))/size_of_line >=min_points:
  File "/usr/lib64/python2.6/genericpath.py", line 49, in getsize
    return os.stat(filename).st_size
OSError: [Errno 2] No such file or directory: '/scratch/user/architsh/PathSegmentsApril2013/14_29875.txt'
In process #14
In process #7
Process #7 done!
In process #15
Process #15 done!
Process Process-17:
Traceback (most recent call last):
  File "/usr/lib64/python2.6/multiprocessing/process.py", line 232, in _bootstrap
    self.run()
  File "/usr/lib64/python2.6/multiprocessing/process.py", line 88, in run
    self._target(*self._args, **self._kwargs)
  File "Strong_Paths.py", line 25, in legit
    if float(os.path.getsize(sys.argv[2]+'/'+str(process_num)+'_'+str(i)+'.txt'))/size_of_line >=min_points:
  File "/usr/lib64/python2.6/genericpath.py", line 49, in getsize
    return os.stat(filename).st_size
OSError: [Errno 2] No such file or directory: '/scratch/user/architsh/PathSegmentsApril2013/17_47088.txt'
In process #17
In process #5
Process #5 done!
Traceback (most recent call last):
  File "Strong_Paths.py", line 40, in <module>
Process Process-3:
Traceback (most recent call last):
  File "/usr/lib64/python2.6/multiprocessing/process.py", line 232, in _bootstrap
    self.run()
  File "/usr/lib64/python2.6/multiprocessing/process.py", line 88, in run
    self._target(*self._args, **self._kwargs)
  File "Strong_Paths.py", line 25, in legit
Process Process-19:
Traceback (most recent call last):
  File "/usr/lib64/python2.6/multiprocessing/process.py", line 232, in _bootstrap
    self.run()
  File "/usr/lib64/python2.6/multiprocessing/process.py", line 88, in run
    self._target(*self._args, **self._kwargs)
  File "Strong_Paths.py", line 25, in legit
Process Process-8:
Traceback (most recent call last):
  File "/usr/lib64/python2.6/multiprocessing/process.py", line 232, in _bootstrap
    self.run()
  File "/usr/lib64/python2.6/multiprocessing/process.py", line 88, in run
    self._target(*self._args, **self._kwargs)
  File "Strong_Paths.py", line 25, in legit
    main()
  File "Strong_Paths.py", line 37, in main
    if float(os.path.getsize(sys.argv[2]+'/'+str(process_num)+'_'+str(i)+'.txt'))/size_of_line >=min_points:
    if float(os.path.getsize(sys.argv[2]+'/'+str(process_num)+'_'+str(i)+'.txt'))/size_of_line >=min_points:
    if float(os.path.getsize(sys.argv[2]+'/'+str(process_num)+'_'+str(i)+'.txt'))/size_of_line >=min_points:
      File "/usr/lib64/python2.6/genericpath.py", line 49, in getsize
  File "/usr/lib64/python2.6/genericpath.py", line 49, in getsize
process_list[i].join()
  File "/usr/lib64/python2.6/genericpath.py", line 49, in getsize
  File "/usr/lib64/python2.6/multiprocessing/process.py", line 119, in join
    res = self._popen.wait(timeout)
    return os.stat(filename).st_size
    return os.stat(filename).st_size
  File "/usr/lib64/python2.6/multiprocessing/forking.py", line 122, in wait
    return os.stat(filename).st_size
KeyboardInterrupt
KeyboardInterrupt
    return self.poll(0)
KeyboardInterrupt
  File "/usr/lib64/python2.6/multiprocessing/forking.py", line 107, in poll
    pid, sts = os.waitpid(self.pid, flag)
KeyboardInterrupt
In process #19
In process #3
In process #8
Terminated
